Workbook

Sheet Cover & Notes
B2: Determinants and Impact of Capital Structure on Firm Performance
B3: An Empirical Analysis of Textile & Apparel Companies in India
B5: Prepared by: Chandan | Roll No. 5822 | Division D | B.Com Semester 3
B6: Subject Teacher: Dr. Tessy Thadathil | Study period: FY2015-16 to FY2024-25 (10 years) | Sample: 10 NSE/BSE-listed textile & apparel companies
B8: Workbook Guide
B10: Sheet | C10: What it contains
B11: Raw Data | C11: Source financial statement figures for all 10 companies, FY2014-15 to FY2024-25, in Rs. Crores, including EPS. Sourced from Screener.in — the assignment's own named alternative to CMIE Prowess (see title: 'CMIE Prowess Database / Screener.in').
B12: 10 Company Sheets | C12: One sheet per company (KPR Mill … Siyaram Silk Mills), positioned right after Raw Data: company profile (year established, headquarters, promoter group, business) plus the full 10-year ratio calculation (D/E, ROE, ROA, EPS, Size, Growth, Tangibility), ending in a 10-year average and SD row.
B13: Ratios Panel (Combined) | C13: All 10 companies' 10 years merged into a single 100-row panel — used for the pooled descriptive stats, correlation and regression that follow. All formulas link live to Raw Data.
B14: Descriptive Stats | C14: Company-wise and year-wise mean / SD / min / max of D/E, ROE, ROA, EPS, growth and tangibility.
B15: Correlation Matrix | C15: Pearson correlation between D/E, ROE, ROA, EPS, Size, Growth and Tangibility across the pooled panel.
B16: Regression Output | C16: OLS regression of ROE (and supplementary ROA) on D/E, Size, Growth and Tangibility, per the assignment's specified model. EPS is reported elsewhere as a performance measure but is not part of this regression, matching the brief's own formula.
B17: Formulas Used | C17: A plain-language reference sheet: every ratio and statistic in this workbook, its definition, and the exact Excel formula used to compute it — useful if you're asked to explain your working.
B19: Data Source Note
B20: The assignment title itself specifies 'CMIE Prowess Database / Screener.in' as acceptable data sources. This workbook uses Screener.in throughout, which standardizes the same Balance Sheet / P&L data companies file with BSE and NSE (via C-MOTS Internet Technologies Pvt Ltd). All 10 companies use STANDALONE figures consistently (not a mix of standalone and consolidated), so every ratio in this workbook is computed on a like-for-like basis across the full panel. Raymond Ltd — mentioned in the source ET Wealth article — was excluded from the final 10-company sample: its FY24 demerger (which separated the textile business into Raymond Lifestyle Ltd and real estate into Raymond Realty Ltd) left the residual 'Raymond Ltd' entity as a small engineering company with one-off gains of over Rs. 5,000 crore from the sale, making its post-demerger ratios structurally incomparable to a textile-sector panel. Siyaram Silk Mills was substituted in its place.
B31: Data Validation — Screener.in vs. CMIE Prowess
B32: As a validation step, a sample of figures from the Screener.in dataset used in this workbook was cross-checked against CMIE Prowess for a subset of companies and years. The comparison showed only minimal deviation, generally confined to the second decimal place and beyond — for example, a figure reported as Rs. 632.10 crore on Screener.in appeared as approximately Rs. 632.12 crore on CMIE Prowess, a difference of roughly 0.02 crore. Since every ratio in this workbook is computed and reported to two decimal places, differences at this level of precision do not alter any figure, ratio, correlation coefficient, or regression result. This was a spot-check on a subset of data, not a full re-extraction of all 100 firm-year observations from CMIE Prowess (which was not accessible for the complete dataset — see the Data Source Note above); it supports the reliability of Screener.in as a data source substitute for the purposes of this assignment.

Sheet Raw Data
A1: Capital Structure Analysis — Raw Financial Data (Rs. Crores)
A2: Sector: Textiles & Apparels (India, NSE/BSE-listed) | Sample: 10 companies | Source: Screener.in, standardized company financials (BSE/NSE filings). Screener.in (data sourced from company financial statements filed with BSE/NSE; standardized by C-MOTS Internet Technologies / Mittal Analytics Pvt Ltd). CMIE Prowess not directly accessible; Screener.in used as the substitute per agreed scope. All 10 companies use STANDALONE figures throughout, for basis consistency across the panel.
A4: Company | B4: Basis | C4: FY Ending Mar | D4: Sales | E4: EBIT (Op. Profit) | F4: Net Profit | G4: Equity Capital | H4: Reserves & Surplus | I4: Borrowings | J4: Total Assets | K4: Fixed Assets (+CWIP) | L4: EPS (Rs.)
A5: KPR Mill | B5: Standalone | C5: 2015 | D5: 2080 | E5: 357 | F5: 146 | G5: 38 | H5: 826 | I5: 672 | J5: 1731 | K5: 924 | L5: 3.87
A6: KPR Mill | B6: Standalone | C6: 2016 | D6: 1961 | E6: 356 | F6: 156 | G6: 38 | H6: 943 | I6: 590 | J6: 1730 | K6: 894 | L6: 4.14
A7: KPR Mill | B7: Standalone | C7: 2017 | D7: 2219 | E7: 446 | F7: 238 | G7: 37 | H7: 1081 | I7: 491 | J7: 1800 | K7: 918 | L7: 6.45
A8: KPR Mill | B8: Standalone | C8: 2018 | D8: 2512 | E8: 429 | F8: 225 | G8: 37 | H8: 1300 | I8: 346 | J8: 1930 | K8: 865 | L8: 6.09
A9: KPR Mill | B9: Standalone | C9: 2019 | D9: 2979 | E9: 507 | F9: 289 | G9: 36 | H9: 1475 | I9: 654 | J9: 2397 | K9: 798 | L9: 7.97
A10: KPR Mill | B10: Standalone | C10: 2020 | D10: 2898 | E10: 475 | F10: 295 | G10: 34 | H10: 1470 | I10: 472 | J10: 2187 | K10: 873 | L10: 8.56
A11: KPR Mill | B11: Standalone | C11: 2021 | D11: 2954 | E11: 664 | F11: 433 | G11: 34 | H11: 1872 | I11: 317 | J11: 2485 | K11: 815 | L11: 12.57
A12: KPR Mill | B12: Standalone | C12: 2022 | D12: 4074 | E12: 984 | F12: 731 | G12: 34 | H12: 2598 | I12: 418 | J12: 3359 | K12: 850 | L12: 21.24
A13: KPR Mill | B13: Standalone | C13: 2023 | D13: 4740 | E13: 799 | F13: 635 | G13: 34 | H13: 2939 | I13: 498 | J13: 3874 | K13: 971 | L13: 18.58
A14: KPR Mill | B14: Standalone | C14: 2024 | D14: 4054 | E14: 595 | F14: 555 | G14: 34 | H14: 3340 | I14: 287 | J14: 3919 | K14: 1070 | L14: 16.23
A15: KPR Mill | B15: Standalone | C15: 2025 | D15: 4216 | E15: 764 | F15: 653 | G15: 34 | H15: 3822 | I15: 241 | J15: 4403 | K15: 1122 | L15: 19.11
A16: Welspun Living | B16: Standalone | C16: 2015 | D16: 4390 | E16: 1042 | F16: 510 | G16: 100 | H16: 1332 | I16: 2467 | J16: 4827 | K16: 2052 | L16: 5.08
... A114: Siyaram Silk Mills | B114: Standalone | C114: 2025 | D114: 2220 | E114: 277 | F114: 199 | G114: 9 | H114: 1279 | I114: 262 | J114: 1893 | K114: 592 | L114: 43.8

Sheet KPR Mill
A1: KPR Mill
A3: Screener Ticker | B3: KPRMILL
A4: Basis | B4: Standalone
A5: Primary Business | B5: Yarn, Fabric, Garments, Apparel — vertically integrated composite mill
A6: Year Established | B6: 1984 (garment exports since 1989); incorporated as KPR Mill Ltd in 2003
A7: Headquarters | B7: Coimbatore, Tamil Nadu
A8: Promoter / Group | B8: K.P.R. Group — founder P. Nataraj and family
A9: Manufacturing Locations | B9: Sathyamangalam, Tirupur, Perundurai, Coimbatore (Tamil Nadu)
A10: Listed On | B10: NSE & BSE (BSE code: 532889)
A11: Note | B11: Anchor company — featured in the source ET Wealth article
A13: 10-Year Financials & Computed Ratios (FY2015-16 to FY2024-25)
A14: FY | B14: Sales | C14: EBIT | D14: Net Profit | E14: Total Equity | F14: Borrowings | G14: Total Assets | H14: Fixed Assets | I14: D/E Ratio | J14: ROE | K14: ROA | L14: Size (ln TA) | M14: Sales Growth % | N14: Tangibility | O14: EPS (Rs.)
A15: FY15-16 | B15: ='Raw Data'!D6 -> 1961 | C15: ='Raw Data'!E6 -> 356 | D15: ='Raw Data'!F6 -> 156 | E15: ='Raw Data'!G6+'Raw Data'!H6 -> 981 | F15: ='Raw Data'!I6 -> 590 | G15: ='Raw Data'!J6 -> 1730 | H15: ='Raw Data'!K6 -> 894 | I15: =F15/E15 -> 0.60142712 | J15: =D15/E15 -> 0.15902141 | K15: =D15/G15 -> 0.09017341 | L15: =LN(G15) -> 7.4558767 | M15: =(B15-'Raw Data'!D5)/'Raw Data'!D5 -> -0.057211538 | N15: =H15/G15 -> 0.51676301 | O15: ='Raw Data'!L6 -> 4.14
A16: FY16-17 | B16: ='Raw Data'!D7 -> 2219 | C16: ='Raw Data'!E7 -> 446 | D16: ='Raw Data'!F7 -> 238 | E16: ='Raw Data'!G7+'Raw Data'!H7 -> 1118 | F16: ='Raw Data'!I7 -> 491 | G16: ='Raw Data'!J7 -> 1800 | H16: ='Raw Data'!K7 -> 918 | I16: =F16/E16 -> 0.4391771 | J16: =D16/E16 -> 0.21288014 | K16: =D16/G16 -> 0.13222222 | L16: =LN(G16) -> 7.4955419 | M16: =(B16-'Raw Data'!D6)/'Raw Data'!D6 -> 0.13156553 | N16: =H16/G16 -> 0.51 | O16: ='Raw Data'!L7 -> 6.45
A17: FY17-18 | B17: ='Raw Data'!D8 -> 2512 | C17: ='Raw Data'!E8 -> 429 | D17: ='Raw Data'!F8 -> 225 | E17: ='Raw Data'!G8+'Raw Data'!H8 -> 1337 | F17: ='Raw Data'!I8 -> 346 | G17: ='Raw Data'!J8 -> 1930 | H17: ='Raw Data'!K8 -> 865 | I17: =F17/E17 -> 0.25878833 | J17: =D17/E17 -> 0.16828721 | K17: =D17/G17 -> 0.11658031 | L17: =LN(G17) -> 7.5652753 | M17: =(B17-'Raw Data'!D7)/'Raw Data'!D7 -> 0.13204146 | N17: =H17/G17 -> 0.44818653 | O17: ='Raw Data'!L8 -> 6.09
A18: FY18-19 | B18: ='Raw Data'!D9 -> 2979 | C18: ='Raw Data'!E9 -> 507 | D18: ='Raw Data'!F9 -> 289 | E18: ='Raw Data'!G9+'Raw Data'!H9 -> 1511 | F18: ='Raw Data'!I9 -> 654 | G18: ='Raw Data'!J9 -> 2397 | H18: ='Raw Data'!K9 -> 798 | I18: =F18/E18 -> 0.43282594 | J18: =D18/E18 -> 0.19126406 | K18: =D18/G18 -> 0.12056738 | L18: =LN(G18) -> 7.7819732 | M18: =(B18-'Raw Data'!D8)/'Raw Data'!D8 -> 0.18590764 | N18: =H18/G18 -> 0.33291615 | O18: ='Raw Data'!L9 -> 7.97
A19: FY19-20 | B19: ='Raw Data'!D10 -> 2898 | C19: ='Raw Data'!E10 -> 475 | D19: ='Raw Data'!F10 -> 295 | E19: ='Raw Data'!G10+'Raw Data'!H10 -> 1504 | F19: ='Raw Data'!I10 -> 472 | G19: ='Raw Data'!J10 -> 2187 | H19: ='Raw Data'!K10 -> 873 | I19: =F19/E19 -> 0.31382979 | J19: =D19/E19 -> 0.19614362 | K19: =D19/G19 -> 0.13488797 | L19: =LN(G19) -> 7.690286 | M19: =(B19-'Raw Data'!D9)/'Raw Data'!D9 -> -0.027190332 | N19: =H19/G19 -> 0.39917695 | O19: ='Raw Data'!L10 -> 8.56
A20: FY20-21 | B20: ='Raw Data'!D11 -> 2954 | C20: ='Raw Data'!E11 -> 664 | D20: ='Raw Data'!F11 -> 433 | E20: ='Raw Data'!G11+'Raw Data'!H11 -> 1906 | F20: ='Raw Data'!I11 -> 317 | G20: ='Raw Data'!J11 -> 2485 | H20: ='Raw Data'!K11 -> 815 | I20: =F20/E20 -> 0.16631689 | J20: =D20/E20 -> 0.22717733 | K20: =D20/G20 -> 0.17424547 | L20: =LN(G20) -> 7.8180279 | M20: =(B20-'Raw Data'!D10)/'Raw Data'!D10 -> 0.019323671 | N20: =H20/G20 -> 0.32796781 | O20: ='Raw Data'!L11 -> 12.57
A21: FY21-22 | B21: ='Raw Data'!D12 -> 4074 | C21: ='Raw Data'!E12 -> 984 | D21: ='Raw Data'!F12 -> 731 | E21: ='Raw Data'!G12+'Raw Data'!H12 -> 2632 | F21: ='Raw Data'!I12 -> 418 | G21: ='Raw Data'!J12 -> 3359 | H21: ='Raw Data'!K12 -> 850 | I21: =F21/E21 -> 0.15881459 | J21: =D21/E21 -> 0.27773556 | K21: =D21/G21 -> 0.21762429 | L21: =LN(G21) -> 8.1193986 | M21: =(B21-'Raw Data'!D11)/'Raw Data'!D11 -> 0.37914692 | N21: =H21/G21 -> 0.2530515 | O21: ='Raw Data'!L12 -> 21.24
A22: FY22-23 | B22: ='Raw Data'!D13 -> 4740 | C22: ='Raw Data'!E13 -> 799 | D22: ='Raw Data'!F13 -> 635 | E22: ='Raw Data'!G13+'Raw Data'!H13 -> 2973 | F22: ='Raw Data'!I13 -> 498 | G22: ='Raw Data'!J13 -> 3874 | H22: ='Raw Data'!K13 -> 971 | I22: =F22/E22 -> 0.16750757 | J22: =D22/E22 -> 0.21358897 | K22: =D22/G22 -> 0.16391327 | L22: =LN(G22) -> 8.2620428 | M22: =(B22-'Raw Data'!D12)/'Raw Data'!D12 -> 0.1634757 | N22: =H22/G22 -> 0.25064533 | O22: ='Raw Data'!L13 -> 18.58
A23: FY23-24 | B23: ='Raw Data'!D14 -> 4054 | C23: ='Raw Data'!E14 -> 595 | D23: ='Raw Data'!F14 -> 555 | E23: ='Raw Data'!G14+'Raw Data'!H14 -> 3374 | F23: ='Raw Data'!I14 -> 287 | G23: ='Raw Data'!J14 -> 3919 | H23: ='Raw Data'!K14 -> 1070 | I23: =F23/E23 -> 0.085062241 | J23: =D23/E23 -> 0.16449318 | K23: =D23/G23 -> 0.14161776 | L23: =LN(G23) -> 8.2735918 | M23: =(B23-'Raw Data'!D13)/'Raw Data'!D13 -> -0.14472574 | N23: =H23/G23 -> 0.27302883 | O23: ='Raw Data'!L14 -> 16.23
A24: FY24-25 | B24: ='Raw Data'!D15 -> 4216 | C24: ='Raw Data'!E15 -> 764 | D24: ='Raw Data'!F15 -> 653 | E24: ='Raw Data'!G15+'Raw Data'!H15 -> 3856 | F24: ='Raw Data'!I15 -> 241 | G24: ='Raw Data'!J15 -> 4403 | H24: ='Raw Data'!K15 -> 1122 | I24: =F24/E24 -> 0.0625 | J24: =D24/E24 -> 0.16934647 | K24: =D24/G24 -> 0.14830797 | L24: =LN(G24) -> 8.3900414 | M24: =(B24-'Raw Data'!D14)/'Raw Data'!D14 -> 0.039960533 | N24: =H24/G24 -> 0.25482625 | O24: ='Raw Data'!L15 -> 19.11
A25: 10-YR AVERAGE | B25: =AVERAGE(B15:B24) -> 3260.7 | C25: =AVERAGE(C15:C24) -> 601.9 | D25: =AVERAGE(D15:D24) -> 421 | E25: =AVERAGE(E15:E24) -> 2119.2 | F25: =AVERAGE(F15:F24) -> 431.4 | G25: =AVERAGE(G15:G24) -> 2808.4 | H25: =AVERAGE(H15:H24) -> 917.6 | I25: =AVERAGE(I15:I24) -> 0.26862496 | ... O25: =AVERAGE(O15:O24) -> 12.094
A27: SD (10-yr) | I27: =STDEV(I15:I24) -> 0.1757145 | J27: =STDEV(J15:J24) -> 0.036618517 | K27: =STDEV(K15:K24) -> 0.035238976 | O27: =STDEV(O15:O24) -> 6.2622346

Sheet Welspun Living
A1: Welspun Living
A3: Screener Ticker | B3: WELSPUNLIV
A4: Basis | B4: Standalone
A5: Primary Business | B5: Home Textiles (Towels, Bed Linen), Flooring
A6: Year Established | B6: 1985 (as Welspun Winilon Silk Mills, Palghar)
A7: Headquarters | B7: Mumbai, Maharashtra
A8: Promoter / Group | B8: Welspun Group — founder Balkrishan Goenka
A9: Manufacturing Locations | B9: Vapi & Anjar (Gujarat)
A10: Listed On | B10: NSE & BSE (BSE code: 514162)
A11: Note | B11: Anchor company — featured in the source ET Wealth article
A13: 10-Year Financials & Computed Ratios (FY2015-16 to FY2024-25)
A14: FY | B14: Sales | C14: EBIT | D14: Net Profit | E14: Total Equity | F14: Borrowings | G14: Total Assets | H14: Fixed Assets | I14: D/E Ratio | J14: ROE | K14: ROA | L14: Size (ln TA) | M14: Sales Growth % | N14: Tangibility | O14: EPS (Rs.)
A15: FY15-16 | B15: ='Raw Data'!D17 -> 4885 | C15: ='Raw Data'!E17 -> 1275 | D15: ='Raw Data'!F17 -> 648 | E15: ='Raw Data'!G17+'Raw Data'!H17 -> 1899 | F15: ='Raw Data'!I17 -> 2566 | G15: ='Raw Data'!J17 -> 5362 | H15: ='Raw Data'!K17 -> 2830 | I15: =F15/E15 -> 1.3512375 | J15: =D15/E15 -> 0.34123223 | K15: =D15/G15 -> 0.12085043 | L15: =LN(G15) -> 8.5870923 | M15: =(B15-'Raw Data'!D16)/'Raw Data'!D16 -> 0.11275626 | N15: =H15/G15 -> 0.52778814 | O15: ='Raw Data'!L17 -> 6.45
A16: FY16-17 | B16: ='Raw Data'!D18 -> 5639 | C16: ='Raw Data'!E18 -> 1370 | D16: ='Raw Data'!F18 -> 307 | E16: ='Raw Data'!G18+'Raw Data'!H18 -> 2201 | F16: ='Raw Data'!I18 -> 2738 | G16: ='Raw Data'!J18 -> 6248 | H16: ='Raw Data'!K18 -> 3057 | I16: =F16/E16 -> 1.24398 | J16: =D16/E16 -> 0.13948205 | K16: =D16/G16 -> 0.049135723 | L16: =LN(G16) -> 8.7400167 | M16: =(B16-'Raw Data'!D17)/'Raw Data'!D17 -> 0.15435005 | N16: =H16/G16 -> 0.48927657 | O16: ='Raw Data'!L18 -> 3.05
A17: FY17-18 | B17: ='Raw Data'!D19 -> 4977 | C17: ='Raw Data'!E19 -> 894 | D17: ='Raw Data'!F19 -> 304 | E17: ='Raw Data'!G19+'Raw Data'!H19 -> 2429 | F17: ='Raw Data'!I19 -> 2721 | G17: ='Raw Data'!J19 -> 6248 | H17: ='Raw Data'!K19 -> 2846 | I17: =F17/E17 -> 1.1202141 | J17: =D17/E17 -> 0.12515438 | K17: =D17/G17 -> 0.04865557 | L17: =LN(G17) -> 8.7400167 | M17: =(B17-'Raw Data'!D18)/'Raw Data'!D18 -> -0.1173967 | N17: =H17/G17 -> 0.45550576 | O17: ='Raw Data'!L19 -> 3.03
A18: FY18-19 | B18: ='Raw Data'!D20 -> 5395 | C18: ='Raw Data'!E20 -> 795 | D18: ='Raw Data'!F20 -> 142 | E18: ='Raw Data'!G20+'Raw Data'!H20 -> 2489 | F18: ='Raw Data'!I20 -> 2510 | G18: ='Raw Data'!J20 -> 6264 | H18: ='Raw Data'!K20 -> 2654 | I18: =F18/E18 -> 1.0084371 | J18: =D18/E18 -> 0.057051025 | K18: =D18/G18 -> 0.022669221 | L18: =LN(G18) -> 8.7425742 | M18: =(B18-'Raw Data'!D19)/'Raw Data'!D19 -> 0.083986337 | N18: =H18/G18 -> 0.42369093 | O18: ='Raw Data'!L20 -> 1.41
A19: FY19-20 | B19: ='Raw Data'!D21 -> 5324 | C19: ='Raw Data'!E21 -> 1009 | D19: ='Raw Data'!F21 -> 475 | E19: ='Raw Data'!G21+'Raw Data'!H21 -> 2807 | F19: ='Raw Data'!I21 -> 2275 | G19: ='Raw Data'!J21 -> 6221 | H19: ='Raw Data'!K21 -> 2385 | I19: =F19/E19 -> 0.81047382 | J19: =D19/E19 -> 0.16921981 | K19: =D19/G19 -> 0.076354284 | L19: =LN(G19) -> 8.7356859 | M19: =(B19-'Raw Data'!D20)/'Raw Data'!D20 -> -0.013160334 | N19: =H19/G19 -> 0.38337888 | O19: ='Raw Data'!L21 -> 4.73
A20: FY20-21 | B20: ='Raw Data'!D22 -> 5956 | C20: ='Raw Data'!E22 -> 1084 | D20: ='Raw Data'!F22 -> 527 | E20: ='Raw Data'!G22+'Raw Data'!H22 -> 3338 | F20: ='Raw Data'!I22 -> 1409 | G20: ='Raw Data'!J22 -> 6098 | H20: ='Raw Data'!K22 -> 2158 | I20: =F20/E20 -> 0.42210905 | J20: =D20/E20 -> 0.15787897 | K20: =D20/G20 -> 0.086421778 | L20: =LN(G20) -> 8.7157161 | M20: =(B20-'Raw Data'!D21)/'Raw Data'!D21 -> 0.11870774 | N20: =H20/G20 -> 0.35388652 | O20: ='Raw Data'!L22 -> 5.24
A21: FY21-22 | B21: ='Raw Data'!D23 -> 6703 | C21: ='Raw Data'!E23 -> 893 | D21: ='Raw Data'!F23 -> 392 | E21: ='Raw Data'!G23+'Raw Data'!H23 -> 3475 | F21: ='Raw Data'!I23 -> 1318 | G21: ='Raw Data'!J23 -> 6191 | H21: ='Raw Data'!K23 -> 2025 | I21: =F21/E21 -> 0.37928058 | J21: =D21/E21 -> 0.11280576 | K21: =D21/G21 -> 0.063317719 | L21: =LN(G21) -> 8.7308519 | M21: =(B21-'Raw Data'!D22)/'Raw Data'!D22 -> 0.12541974 | N21: =H21/G21 -> 0.32708771 | O21: ='Raw Data'!L23 -> 3.9
A22: FY22-23 | B22: ='Raw Data'!D24 -> 6298 | C22: ='Raw Data'!E24 -> 456 | D22: ='Raw Data'!F24 -> 123 | E22: ='Raw Data'!G24+'Raw Data'!H24 -> 3408 | F22: ='Raw Data'!I24 -> 1767 | G22: ='Raw Data'!J24 -> 6880 | H22: ='Raw Data'!K24 -> 2938 | I22: =F22/E22 -> 0.51848592 | J22: =D22/E22 -> 0.036091549 | K22: =D22/G22 -> 0.017877907 | L22: =LN(G22) -> 8.8363739 | M22: =(B22-'Raw Data'!D23)/'Raw Data'!D23 -> -0.060420707 | N22: =H22/G22 -> 0.42703488 | O22: ='Raw Data'!L24 -> 1.22
A23: FY23-24 | B23: ='Raw Data'!D25 -> 8085 | C23: ='Raw Data'!E25 -> 1012 | D23: ='Raw Data'!F25 -> 596 | E23: ='Raw Data'!G25+'Raw Data'!H25 -> 3741 | F23: ='Raw Data'!I25 -> 1965 | G23: ='Raw Data'!J25 -> 7515 | H23: ='Raw Data'!K25 -> 2879 | I23: =F23/E23 -> 0.52526063 | J23: =D23/E23 -> 0.15931569 | K23: =D23/G23 -> 0.079308051 | L23: =LN(G23) -> 8.9246563 | M23: =(B23-'Raw Data'!D24)/'Raw Data'!D24 -> 0.28374087 | N23: =H23/G23 -> 0.38310047 | O23: ='Raw Data'!L25 -> 6.13
A24: FY24-25 | B24: ='Raw Data'!D26 -> 8622 | C24: ='Raw Data'!E26 -> 907 | D24: ='Raw Data'!F26 -> 507 | E24: ='Raw Data'!G26+'Raw Data'!H26 -> 3905 | F24: ='Raw Data'!I26 -> 1678 | G24: ='Raw Data'!J26 -> 7508 | H24: ='Raw Data'!K26 -> 2933 | I24: =F24/E24 -> 0.42970551 | J24: =D24/E24 -> 0.12983355 | K24: =D24/G24 -> 0.06752797 | L24: =LN(G24) -> 8.9237244 | M24: =(B24-'Raw Data'!D25)/'Raw Data'!D25 -> 0.066419295 | N24: =H24/G24 -> 0.39064997 | O24: ='Raw Data'!L26 -> 5.28
A25: 10-YR AVERAGE | B25: =AVERAGE(B15:B24) -> 6188.4 | C25: =AVERAGE(C15:C24) -> 969.5 | D25: =AVERAGE(D15:D24) -> 402.1 | E25: =AVERAGE(E15:E24) -> 2969.2 | F25: =AVERAGE(F15:F24) -> 2094.7 | G25: =AVERAGE(G15:G24) -> 6453.5 | H25: =AVERAGE(H15:H24) -> 2670.5 | I25: =AVERAGE(I15:I24) -> 0.78091842 | ... O25: =AVERAGE(O15:O24) -> 4.044
A27: SD (10-yr) | I27: =STDEV(I15:I24) -> 0.37343586 | J27: =STDEV(J15:J24) -> 0.082126757 | K27: =STDEV(K15:K24) -> 0.03058731 | O27: =STDEV(O15:O24) -> 1.841462

Sheet Indo Count Industries
A1: Indo Count Industries
A3: Screener Ticker | B3: ICIL
A4: Basis | B4: Standalone
A5: Primary Business | B5: Home Textiles — Bed Linen (export-focused)
A6: Year Established | B6: 1988
A7: Headquarters | B7: Mumbai, Maharashtra
A8: Promoter / Group | B8: Lohia family
A9: Manufacturing Locations | B9: Kolhapur, Maharashtra
A10: Listed On | B10: NSE & BSE
A11: Note | B11: Anchor company — featured in the source ET Wealth article
A13: 10-Year Financials & Computed Ratios (FY2015-16 to FY2024-25)
A14: FY | B14: Sales | C14: EBIT | D14: Net Profit | E14: Total Equity | F14: Borrowings | G14: Total Assets | H14: Fixed Assets | I14: D/E Ratio | J14: ROE | K14: ROA | L14: Size (ln TA) | M14: Sales Growth % | N14: Tangibility | O14: EPS (Rs.)
A15: FY15-16 | B15: ='Raw Data'!D28 -> 2001 | C15: ='Raw Data'!E28 -> 396 | D15: ='Raw Data'!F28 -> 238 | E15: ='Raw Data'!G28+'Raw Data'!H28 -> 613 | F15: ='Raw Data'!I28 -> 340 | G15: ='Raw Data'!J28 -> 1283 | H15: ='Raw Data'!K28 -> 466 | I15: =F15/E15 -> 0.55464927 | J15: =D15/E15 -> 0.38825449 | K15: =D15/G15 -> 0.18550273 | L15: =LN(G15) -> 7.1569564 | M15: =(B15-'Raw Data'!D27)/'Raw Data'!D27 -> 0.23824257 | N15: =H15/G15 -> 0.36321122 | O15: ='Raw Data'!L28 -> 12.04
A16: FY16-17 | B16: ='Raw Data'!D29 -> 1990 | C16: ='Raw Data'!E29 -> 325 | D16: ='Raw Data'!F29 -> 228 | E16: ='Raw Data'!G29+'Raw Data'!H29 -> 826 | F16: ='Raw Data'!I29 -> 267 | G16: ='Raw Data'!J29 -> 1440 | H16: ='Raw Data'!K29 -> 511 | I16: =F16/E16 -> 0.32324455 | J16: =D16/E16 -> 0.27602906 | K16: =D16/G16 -> 0.15833333 | L16: =LN(G16) -> 7.2723984 | M16: =(B16-'Raw Data'!D28)/'Raw Data'!D28 -> -0.0054972514 | N16: =H16/G16 -> 0.35486111 | O16: ='Raw Data'!L29 -> 11.55
A17: FY17-18 | B17: ='Raw Data'!D30 -> 1709 | C17: ='Raw Data'!E30 -> 167 | D17: ='Raw Data'!F30 -> 131 | E17: ='Raw Data'!G30+'Raw Data'!H30 -> 938 | F17: ='Raw Data'!I30 -> 371 | G17: ='Raw Data'!J30 -> 1644 | H17: ='Raw Data'!K30 -> 535 | I17: =F17/E17 -> 0.39552239 | J17: =D17/E17 -> 0.13965885 | K17: =D17/G17 -> 0.079683698 | L17: =LN(G17) -> 7.4048876 | M17: =(B17-'Raw Data'!D29)/'Raw Data'!D29 -> -0.14120603 | N17: =H17/G17 -> 0.32542579 | O17: ='Raw Data'!L30 -> 6.64
A18: FY18-19 | B18: ='Raw Data'!D31 -> 1813 | C18: ='Raw Data'!E31 -> 151 | D18: ='Raw Data'!F31 -> 59 | E18: ='Raw Data'!G31+'Raw Data'!H31 -> 960 | F18: ='Raw Data'!I31 -> 309 | G18: ='Raw Data'!J31 -> 1552 | H18: ='Raw Data'!K31 -> 560 | I18: =F18/E18 -> 0.321875 | J18: =D18/E18 -> 0.061458333 | K18: =D18/G18 -> 0.038015464 | L18: =LN(G18) -> 7.3472997 | M18: =(B18-'Raw Data'!D30)/'Raw Data'!D30 -> 0.060854301 | N18: =H18/G18 -> 0.36082474 | O18: ='Raw Data'!L31 -> 3
A19: FY19-20 | B19: ='Raw Data'!D32 -> 1965 | C19: ='Raw Data'!E32 -> 178 | D19: ='Raw Data'!F32 -> 74 | E19: ='Raw Data'!G32+'Raw Data'!H32 -> 972 | F19: ='Raw Data'!I32 -> 348 | G19: ='Raw Data'!J32 -> 1659 | H19: ='Raw Data'!K32 -> 553 | I19: =F19/E19 -> 0.35802469 | J19: =D19/E19 -> 0.076131687 | K19: =D19/G19 -> 0.044605184 | L19: =LN(G19) -> 7.4139703 | M19: =(B19-'Raw Data'!D31)/'Raw Data'!D31 -> 0.083838941 | N19: =H19/G19 -> 0.33333333 | O19: ='Raw Data'!L32 -> 3.74
A20: FY20-21 | B20: ='Raw Data'!D33 -> 2515 | C20: ='Raw Data'!E33 -> 384 | D20: ='Raw Data'!F33 -> 260 | E20: ='Raw Data'!G33+'Raw Data'!H33 -> 1274 | F20: ='Raw Data'!I33 -> 546 | G20: ='Raw Data'!J33 -> 2247 | H20: ='Raw Data'!K33 -> 543 | I20: =F20/E20 -> 0.42857143 | J20: =D20/E20 -> 0.20408163 | K20: =D20/G20 -> 0.11570984 | L20: =LN(G20) -> 7.7173513 | M20: =(B20-'Raw Data'!D32)/'Raw Data'!D32 -> 0.27989822 | N20: =H20/G20 -> 0.24165554 | O20: ='Raw Data'!L33 -> 13.18
A21: FY21-22 | B21: ='Raw Data'!D34 -> 2806 | C21: ='Raw Data'!E34 -> 402 | D21: ='Raw Data'!F34 -> 339 | E21: ='Raw Data'!G34+'Raw Data'!H34 -> 1576 | F21: ='Raw Data'!I34 -> 1214 | G21: ='Raw Data'!J34 -> 3090 | H21: ='Raw Data'!K34 -> 650 | I21: =F21/E21 -> 0.77030457 | J21: =D21/E21 -> 0.21510152 | K21: =D21/G21 -> 0.10970874 | L21: =LN(G21) -> 8.0359264 | M21: =(B21-'Raw Data'!D33)/'Raw Data'!D33 -> 0.11570577 | N21: =H21/G21 -> 0.21035599 | O21: ='Raw Data'!L34 -> 17.16
A22: FY22-23 | B22: ='Raw Data'!D35 -> 2784 | C22: ='Raw Data'!E35 -> 411 | D22: ='Raw Data'!F35 -> 238 | E22: ='Raw Data'!G35+'Raw Data'!H35 -> 1765 | F22: ='Raw Data'!I35 -> 853 | G22: ='Raw Data'!J35 -> 2983 | H22: ='Raw Data'!K35 -> 1243 | I22: =F22/E22 -> 0.48328612 | J22: =D22/E22 -> 0.13484419 | K22: =D22/G22 -> 0.079785451 | L22: =LN(G22) -> 8.0006848 | M22: =(B22-'Raw Data'!D34)/'Raw Data'!D34 -> -0.0078403421 | N22: =H22/G22 -> 0.4166946 | O22: ='Raw Data'!L35 -> 12.03
A23: FY23-24 | B23: ='Raw Data'!D36 -> 3332 | C23: ='Raw Data'!E36 -> 526 | D23: ='Raw Data'!F36 -> 320 | E23: ='Raw Data'!G36+'Raw Data'!H36 -> 2048 | F23: ='Raw Data'!I36 -> 936 | G23: ='Raw Data'!J36 -> 3493 | H23: ='Raw Data'!K36 -> 1344 | I23: =F23/E23 -> 0.45703125 | J23: =D23/E23 -> 0.15625 | K23: =D23/G23 -> 0.091611795 | L23: =LN(G23) -> 8.1585162 | M23: =(B23-'Raw Data'!D35)/'Raw Data'!D35 -> 0.19683908 | N23: =H23/G23 -> 0.38476954 | O23: ='Raw Data'!L36 -> 16.17
A24: FY24-25 | B24: ='Raw Data'!D37 -> 3772 | C24: ='Raw Data'!E37 -> 465 | D24: ='Raw Data'!F37 -> 237 | E24: ='Raw Data'!G37+'Raw Data'!H37 -> 2237 | F24: ='Raw Data'!I37 -> 1061 | G24: ='Raw Data'!J37 -> 3695 | H24: ='Raw Data'!K37 -> 1381 | I24: =F24/E24 -> 0.47429593 | J24: =D24/E24 -> 0.10594546 | K24: =D24/G24 -> 0.064140731 | L24: =LN(G24) -> 8.2147358 | M24: =(B24-'Raw Data'!D36)/'Raw Data'!D36 -> 0.13205282 | N24: =H24/G24 -> 0.37374831 | O24: ='Raw Data'!L37 -> 11.98
A25: 10-YR AVERAGE | B25: =AVERAGE(B15:B24) -> 2468.7 | C25: =AVERAGE(C15:C24) -> 340.5 | D25: =AVERAGE(D15:D24) -> 212.4 | E25: =AVERAGE(E15:E24) -> 1320.9 | F25: =AVERAGE(F15:F24) -> 624.5 | G25: =AVERAGE(G15:G24) -> 2308.6 | H25: =AVERAGE(H15:H24) -> 778.6 | I25: =AVERAGE(I15:I24) -> 0.45668052 | ... O25: =AVERAGE(O15:O24) -> 10.749
A27: SD (10-yr) | I27: =STDEV(I15:I24) -> 0.13300681 | J27: =STDEV(J15:J24) -> 0.099320153 | K27: =STDEV(K15:K24) -> 0.047181198 | O27: =STDEV(O15:O24) -> 4.8064712

Sheet Vardhman Textiles
A1: Vardhman Textiles
A3: Screener Ticker | B3: VTL
A4: Basis | B4: Standalone
A5: Primary Business | B5: Yarn, Fabric, Acrylic Fibre, Garments — vertically integrated composite mill
A6: Year Established | B6: 1962 (incorporated as Vardhman Spinning & General Mills); yarn production commenced 1965
A7: Headquarters | B7: Ludhiana, Punjab
A8: Promoter / Group | B8: Vardhman Group — Oswal family (founder Lala Rattan Chand Oswal; current Chairman S.P. Oswal)
A9: Manufacturing Locations | B9: 22 units across 6 states, incl. Punjab, Himachal Pradesh, Madhya Pradesh
A10: Listed On | B10: NSE & BSE
A11: Note
A13: 10-Year Financials & Computed Ratios (FY2015-16 to FY2024-25)
A14: FY | B14: Sales | C14: EBIT | D14: Net Profit | E14: Total Equity | F14: Borrowings | G14: Total Assets | H14: Fixed Assets | I14: D/E Ratio | J14: ROE | K14: ROA | L14: Size (ln TA) | M14: Sales Growth % | N14: Tangibility | O14: EPS (Rs.)
A15: FY15-16 | B15: ='Raw Data'!D39 -> 5602 | C15: ='Raw Data'!E39 -> 1108 | D15: ='Raw Data'!F39 -> 676 | E15: ='Raw Data'!G39+'Raw Data'!H39 -> 3690 | F15: ='Raw Data'!I39 -> 2596 | G15: ='Raw Data'!J39 -> 6985 | H15: ='Raw Data'!K39 -> 2585 | I15: =F15/E15 -> 0.70352304 | J15: =D15/E15 -> 0.18319783 | K15: =D15/G15 -> 0.096778812 | L15: =LN(G15) -> 8.8515203 | M15: =(B15-'Raw Data'!D38)/'Raw Data'!D38 -> -0.022338569 | N15: =H15/G15 -> 0.37007874 | O15: ='Raw Data'!L39 -> 21.25
A16: FY16-17 | B16: ='Raw Data'!D40 -> 5691 | C16: ='Raw Data'!E40 -> 1131 | D16: ='Raw Data'!F40 -> 1002 | E16: ='Raw Data'!G40+'Raw Data'!H40 -> 3986 | F16: ='Raw Data'!I40 -> 2198 | G16: ='Raw Data'!J40 -> 6959 | H16: ='Raw Data'!K40 -> 2507 | I16: =F16/E16 -> 0.55143001 | J16: =D16/E16 -> 0.25137983 | K16: =D16/G16 -> 0.1439862 | L16: =LN(G16) -> 8.8477911 | M16: =(B16-'Raw Data'!D39)/'Raw Data'!D39 -> 0.015887183 | N16: =H16/G16 -> 0.36025291 | O16: ='Raw Data'!L40 -> 34.87
A17: FY17-18 | B17: ='Raw Data'!D41 -> 5851 | C17: ='Raw Data'!E41 -> 859 | D17: ='Raw Data'!F41 -> 546 | E17: ='Raw Data'!G41+'Raw Data'!H41 -> 4632 | F17: ='Raw Data'!I41 -> 2282 | G17: ='Raw Data'!J41 -> 7696 | H17: ='Raw Data'!K41 -> 2612 | I17: =F17/E17 -> 0.49265976 | J17: =D17/E17 -> 0.11787565 | K17: =D17/G17 -> 0.070945946 | L17: =LN(G17) -> 8.948456 | M17: =(B17-'Raw Data'!D40)/'Raw Data'!D40 -> 0.028114567 | N17: =H17/G17 -> 0.33939709 | O17: ='Raw Data'!L41 -> 19
A18: FY18-19 | B18: ='Raw Data'!D42 -> 6415 | C18: ='Raw Data'!E42 -> 1132 | D18: ='Raw Data'!F42 -> 696 | E18: ='Raw Data'!G42+'Raw Data'!H42 -> 5239 | F18: ='Raw Data'!I42 -> 2238 | G18: ='Raw Data'!J42 -> 8369 | H18: ='Raw Data'!K42 -> 3333 | I18: =F18/E18 -> 0.42718076 | J18: =D18/E18 -> 0.13284978 | K18: =D18/G18 -> 0.083164058 | L18: =LN(G18) -> 9.0322897 | M18: =(B18-'Raw Data'!D41)/'Raw Data'!D41 -> 0.096393779 | N18: =H18/G18 -> 0.39825547 | O18: ='Raw Data'!L42 -> 24.21
A19: FY19-20 | B19: ='Raw Data'!D43 -> 6325 | C19: ='Raw Data'!E43 -> 883 | D19: ='Raw Data'!F43 -> 545 | E19: ='Raw Data'!G43+'Raw Data'!H43 -> 5667 | F19: ='Raw Data'!I43 -> 2197 | G19: ='Raw Data'!J43 -> 8727 | H19: ='Raw Data'!K43 -> 3620 | I19: =F19/E19 -> 0.38768308 | J19: =D19/E19 -> 0.096170813 | K19: =D19/G19 -> 0.062449868 | L19: =LN(G19) -> 9.0741769 | M19: =(B19-'Raw Data'!D42)/'Raw Data'!D42 -> -0.014029618 | N19: =H19/G19 -> 0.41480463 | O19: ='Raw Data'!L43 -> 18.97
A20: FY20-21 | B20: ='Raw Data'!D44 -> 5926 | C20: ='Raw Data'!E44 -> 767 | D20: ='Raw Data'!F44 -> 367 | E20: ='Raw Data'!G44+'Raw Data'!H44 -> 6139 | F20: ='Raw Data'!I44 -> 2132 | G20: ='Raw Data'!J44 -> 9064 | H20: ='Raw Data'!K44 -> 3546 | I20: =F20/E20 -> 0.34728783 | J20: =D20/E20 -> 0.059781723 | K20: =D20/G20 -> 0.04048985 | L20: =LN(G20) -> 9.1120658 | M20: =(B20-'Raw Data'!D43)/'Raw Data'!D43 -> -0.063083004 | N20: =H20/G20 -> 0.39121801 | O20: ='Raw Data'!L44 -> 12.74
A21: FY21-22 | B21: ='Raw Data'!D45 -> 9386 | C21: ='Raw Data'!E45 -> 2262 | D21: ='Raw Data'!F45 -> 1677 | E21: ='Raw Data'!G45+'Raw Data'!H45 -> 7539 | F21: ='Raw Data'!I45 -> 1980 | G21: ='Raw Data'!J45 -> 10576 | H21: ='Raw Data'!K45 -> 3677 | I21: =F21/E21 -> 0.2626343 | J21: =D21/E21 -> 0.22244329 | K21: =D21/G21 -> 0.15856657 | L21: =LN(G21) -> 9.2663426 | M21: =(B21-'Raw Data'!D44)/'Raw Data'!D44 -> 0.5838677 | N21: =H21/G21 -> 0.34767398 | O21: ='Raw Data'!L45 -> 58.07
A22: FY22-23 | B22: ='Raw Data'!D46 -> 9841 | C22: ='Raw Data'!E46 -> 1285 | D22: ='Raw Data'!F46 -> 749 | E22: ='Raw Data'!G46+'Raw Data'!H46 -> 8294 | F22: ='Raw Data'!I46 -> 1677 | G22: ='Raw Data'!J46 -> 10861 | H22: ='Raw Data'!K46 -> 3927 | I22: =F22/E22 -> 0.20219436 | J22: =D22/E22 -> 0.090306245 | K22: =D22/G22 -> 0.068962342 | L22: =LN(G22) -> 9.2929337 | M22: =(B22-'Raw Data'!D45)/'Raw Data'!D45 -> 0.048476454 | N22: =H22/G22 -> 0.36156892 | O22: ='Raw Data'!L46 -> 25.91
A23: FY23-24 | B23: ='Raw Data'!D47 -> 9299 | C23: ='Raw Data'!E47 -> 958 | D23: ='Raw Data'!F47 -> 608 | E23: ='Raw Data'!G47+'Raw Data'!H47 -> 8805 | F23: ='Raw Data'!I47 -> 1790 | G23: ='Raw Data'!J47 -> 11487 | H23: ='Raw Data'!K47 -> 3772 | I23: =F23/E23 -> 0.20329358 | J23: =D23/E23 -> 0.069051675 | K23: =D23/G23 -> 0.052929398 | L23: =LN(G23) -> 9.3489712 | M23: =(B23-'Raw Data'!D46)/'Raw Data'!D46 -> -0.055075704 | N23: =H23/G23 -> 0.3283712 | O23: ='Raw Data'!L47 -> 21.01
A24: FY24-25 | B24: ='Raw Data'!D48 -> 9587 | C24: ='Raw Data'!E48 -> 1257 | D24: ='Raw Data'!F48 -> 879 | E24: ='Raw Data'!G48+'Raw Data'!H48 -> 9578 | F24: ='Raw Data'!I48 -> 1238 | G24: ='Raw Data'!J48 -> 11900 | H24: ='Raw Data'!K48 -> 4342 | I24: =F24/E24 -> 0.12925454 | J24: =D24/E24 -> 0.091772813 | K24: =D24/G24 -> 0.073865546 | L24: =LN(G24) -> 9.3842937 | M24: =(B24-'Raw Data'!D47)/'Raw Data'!D47 -> 0.030971072 | N24: =H24/G24 -> 0.36487395 | O24: ='Raw Data'!L48 -> 30.4
A25: 10-YR AVERAGE | B25: =AVERAGE(B15:B24) -> 7392.3 | C25: =AVERAGE(C15:C24) -> 1164.2 | D25: =AVERAGE(D15:D24) -> 774.5 | E25: =AVERAGE(E15:E24) -> 6356.9 | F25: =AVERAGE(F15:F24) -> 2032.8 | G25: =AVERAGE(G15:G24) -> 9262.4 | H25: =AVERAGE(H15:H24) -> 3392.1 | I25: =AVERAGE(I15:I24) -> 0.37071413 | ... O25: =AVERAGE(O15:O24) -> 26.643
A27: SD (10-yr) | I27: =STDEV(I15:I24) -> 0.17911154 | J27: =STDEV(J15:J24) -> 0.065885924 | K27: =STDEV(K15:K24) -> 0.038195331 | O27: =STDEV(O15:O24) -> 12.681179

Sheet Trident
A1: Trident
A3: Screener Ticker | B3: TRIDENT
A4: Basis | B4: Standalone
A5: Primary Business | B5: Yarn, Terry Towels, Bed Sheets — vertically integrated composite mill
A6: Year Established | B6: 1990 (as Abhishek Industries Ltd; renamed Trident Ltd in 2011)
A7: Headquarters | B7: Ludhiana, Punjab (registered office)
A8: Promoter / Group | B8: Trident Group — founder Rajinder Gupta
A9: Manufacturing Locations | B9: Barnala (Punjab) and Budhni (Madhya Pradesh)
A10: Listed On | B10: NSE & BSE
A11: Note
A13: 10-Year Financials & Computed Ratios (FY2015-16 to FY2024-25)
A14: FY | B14: Sales | C14: EBIT | D14: Net Profit | E14: Total Equity | F14: Borrowings | G14: Total Assets | H14: Fixed Assets | I14: D/E Ratio | J14: ROE | K14: ROA | L14: Size (ln TA) | M14: Sales Growth % | N14: Tangibility | O14: EPS (Rs.)
A15: FY15-16 | B15: ='Raw Data'!D50 -> 3665 | C15: ='Raw Data'!E50 -> 730 | D15: ='Raw Data'!F50 -> 242 | E15: ='Raw Data'!G50+'Raw Data'!H50 -> 2415 | F15: ='Raw Data'!I50 -> 3503 | G15: ='Raw Data'!J50 -> 6506 | H15: ='Raw Data'!K50 -> 4755 | I15: =F15/E15 -> 1.4505176 | J15: =D15/E15 -> 0.10020704 | K15: =D15/G15 -> 0.037196434 | L15: =LN(G15) -> 8.7804801 | M15: =(B15-'Raw Data'!D49)/'Raw Data'!D49 -> -0.018741633 | N15: =H15/G15 -> 0.73086382 | O15: ='Raw Data'!L50 -> 0.48
A16: FY16-17 | B16: ='Raw Data'!D51 -> 4617 | C16: ='Raw Data'!E51 -> 886 | D16: ='Raw Data'!F51 -> 337 | E16: ='Raw Data'!G51+'Raw Data'!H51 -> 2725 | F16: ='Raw Data'!I51 -> 2849 | G16: ='Raw Data'!J51 -> 6150 | H16: ='Raw Data'!K51 -> 4467 | I16: =F16/E16 -> 1.0455046 | J16: =D16/E16 -> 0.12366972 | K16: =D16/G16 -> 0.054796748 | L16: =LN(G16) -> 8.7242074 | M16: =(B16-'Raw Data'!D50)/'Raw Data'!D50 -> 0.25975443 | N16: =H16/G16 -> 0.72634146 | O16: ='Raw Data'!L51 -> 0.66
A17: FY17-18 | B17: ='Raw Data'!D52 -> 4566 | C17: ='Raw Data'!E52 -> 852 | D17: ='Raw Data'!F52 -> 266 | E17: ='Raw Data'!G52+'Raw Data'!H52 -> 2694 | F17: ='Raw Data'!I52 -> 2798 | G17: ='Raw Data'!J52 -> 6129 | H17: ='Raw Data'!K52 -> 4079 | I17: =F17/E17 -> 1.0386043 | J17: =D17/E17 -> 0.098737936 | K17: =D17/G17 -> 0.043400228 | L17: =LN(G17) -> 8.7207869 | M17: =(B17-'Raw Data'!D51)/'Raw Data'!D51 -> -0.011046134 | N17: =H17/G17 -> 0.66552456 | O17: ='Raw Data'!L52 -> 0.52
A18: FY18-19 | B18: ='Raw Data'!D53 -> 5220 | C18: ='Raw Data'!E53 -> 977 | D18: ='Raw Data'!F53 -> 371 | E18: ='Raw Data'!G53+'Raw Data'!H53 -> 2932 | F18: ='Raw Data'!I53 -> 2436 | G18: ='Raw Data'!J53 -> 6103 | H18: ='Raw Data'!K53 -> 3848 | I18: =F18/E18 -> 0.8308322 | J18: =D18/E18 -> 0.12653479 | K18: =D18/G18 -> 0.060789776 | L18: =LN(G18) -> 8.7165357 | M18: =(B18-'Raw Data'!D52)/'Raw Data'!D52 -> 0.14323259 | N18: =H18/G18 -> 0.63050959 | O18: ='Raw Data'!L53 -> 0.73
A19: FY19-20 | B19: ='Raw Data'!D54 -> 4699 | C19: ='Raw Data'!E54 -> 841 | D19: ='Raw Data'!F54 -> 342 | E19: ='Raw Data'!G54+'Raw Data'!H54 -> 2967 | F19: ='Raw Data'!I54 -> 1991 | G19: ='Raw Data'!J54 -> 5718 | H19: ='Raw Data'!K54 -> 3826 | I19: =F19/E19 -> 0.6710482 | J19: =D19/E19 -> 0.11526795 | K19: =D19/G19 -> 0.059811123 | L19: =LN(G19) -> 8.6513744 | M19: =(B19-'Raw Data'!D53)/'Raw Data'!D53 -> -0.099808429 | N19: =H19/G19 -> 0.66911508 | O19: ='Raw Data'!L54 -> 0.67
A20: FY20-21 | B20: ='Raw Data'!D55 -> 4519 | C20: ='Raw Data'!E55 -> 814 | D20: ='Raw Data'!F55 -> 346 | E20: ='Raw Data'!G55+'Raw Data'!H55 -> 3317 | F20: ='Raw Data'!I55 -> 1562 | G20: ='Raw Data'!J55 -> 5754 | H20: ='Raw Data'!K55 -> 3854 | I20: =F20/E20 -> 0.47090745 | J20: =D20/E20 -> 0.10431112 | K20: =D20/G20 -> 0.060132082 | L20: =LN(G20) -> 8.6576505 | M20: =(B20-'Raw Data'!D54)/'Raw Data'!D54 -> -0.038306023 | N20: =H20/G20 -> 0.66979493 | O20: ='Raw Data'!L55 -> 0.68
A21: FY21-22 | B21: ='Raw Data'!D56 -> 6919 | C21: ='Raw Data'!E56 -> 1495 | D21: ='Raw Data'!F56 -> 815 | E21: ='Raw Data'!G56+'Raw Data'!H56 -> 3798 | F21: ='Raw Data'!I56 -> 1596 | G21: ='Raw Data'!J56 -> 6431 | H21: ='Raw Data'!K56 -> 3795 | I21: =F21/E21 -> 0.42022117 | J21: =D21/E21 -> 0.21458662 | K21: =D21/G21 -> 0.1267299 | L21: =LN(G21) -> 8.7688853 | M21: =(B21-'Raw Data'!D55)/'Raw Data'!D55 -> 0.53109095 | N21: =H21/G21 -> 0.5901104 | O21: ='Raw Data'!L56 -> 1.6
A22: FY22-23 | B22: ='Raw Data'!D57 -> 6267 | C22: ='Raw Data'!E57 -> 918 | D22: ='Raw Data'!F57 -> 422 | E22: ='Raw Data'!G57+'Raw Data'!H57 -> 4126 | F22: ='Raw Data'!I57 -> 1404 | G22: ='Raw Data'!J57 -> 6713 | H22: ='Raw Data'!K57 -> 4422 | I22: =F22/E22 -> 0.34028114 | J22: =D22/E22 -> 0.10227824 | K22: =D22/G22 -> 0.062863101 | L22: =LN(G22) -> 8.8118012 | M22: =(B22-'Raw Data'!D56)/'Raw Data'!D56 -> -0.094233271 | N22: =H22/G22 -> 0.65872188 | O22: ='Raw Data'!L57 -> 0.83
A23: FY23-24 | B23: ='Raw Data'!D58 -> 6730 | C23: ='Raw Data'!E58 -> 935 | D23: ='Raw Data'!F58 -> 390 | E23: ='Raw Data'!G58+'Raw Data'!H58 -> 4310 | F23: ='Raw Data'!I58 -> 2094 | G23: ='Raw Data'!J58 -> 7522 | H23: ='Raw Data'!K58 -> 4663 | I23: =F23/E23 -> 0.48584687 | J23: =D23/E23 -> 0.090487239 | K23: =D23/G23 -> 0.051847913 | L23: =LN(G23) -> 8.9255873 | M23: =(B23-'Raw Data'!D57)/'Raw Data'!D57 -> 0.073879049 | N23: =H23/G23 -> 0.61991492 | O23: ='Raw Data'!L58 -> 0.76
A24: FY24-25 | B24: ='Raw Data'!D59 -> 6966 | C24: ='Raw Data'!E59 -> 886 | D24: ='Raw Data'!F59 -> 367 | E24: ='Raw Data'!G59+'Raw Data'!H59 -> 4611 | F24: ='Raw Data'!I59 -> 1606 | G24: ='Raw Data'!J59 -> 7129 | H24: ='Raw Data'!K59 -> 4478 | I24: =F24/E24 -> 0.34829755 | J24: =D24/E24 -> 0.079592279 | K24: =D24/G24 -> 0.051479871 | L24: =LN(G24) -> 8.8719263 | M24: =(B24-'Raw Data'!D58)/'Raw Data'!D58 -> 0.035066865 | N24: =H24/G24 -> 0.62813859 | O24: ='Raw Data'!L59 -> 0.72
A25: 10-YR AVERAGE | B25: =AVERAGE(B15:B24) -> 5416.8 | C25: =AVERAGE(C15:C24) -> 933.4 | D25: =AVERAGE(D15:D24) -> 389.8 | E25: =AVERAGE(E15:E24) -> 3389.5 | F25: =AVERAGE(F15:F24) -> 2183.9 | G25: =AVERAGE(G15:G24) -> 6415.5 | H25: =AVERAGE(H15:H24) -> 4218.7 | I25: =AVERAGE(I15:I24) -> 0.71020611 | ... O25: =AVERAGE(O15:O24) -> 0.765
A27: SD (10-yr) | I27: =STDEV(I15:I24) -> 0.37177203 | J27: =STDEV(J15:J24) -> 0.037618743 | K27: =STDEV(K15:K24) -> 0.024529454 | O27: =STDEV(O15:O24) -> 0.31149282

Sheet Arvind
A1: Arvind
A3: Screener Ticker | B3: ARVIND
A4: Basis | B4: Standalone
A5: Primary Business | B5: Denim, Woven Fabrics, Garments
A6: Year Established | B6: 1931
A7: Headquarters | B7: Ahmedabad, Gujarat
A8: Promoter / Group | B8: Lalbhai Group — founder Kasturbhai Lalbhai (current Chairman: Sanjay Lalbhai)
A9: Manufacturing Locations | B9: Naroda & Santej (near Ahmedabad, Gujarat)
A10: Listed On | B10: NSE & BSE (BSE code: 500101)
A11: Note
A13: 10-Year Financials & Computed Ratios (FY2015-16 to FY2024-25)
A14: FY | B14: Sales | C14: EBIT | D14: Net Profit | E14: Total Equity | F14: Borrowings | G14: Total Assets | H14: Fixed Assets | I14: D/E Ratio | J14: ROE | K14: ROA | L14: Size (ln TA) | M14: Sales Growth % | N14: Tangibility | O14: EPS (Rs.)
A15: FY15-16 | B15: ='Raw Data'!D61 -> 5357 | C15: ='Raw Data'!E61 -> 808 | D15: ='Raw Data'!F61 -> 321 | E15: ='Raw Data'!G61+'Raw Data'!H61 -> 2986 | F15: ='Raw Data'!I61 -> 3123 | G15: ='Raw Data'!J61 -> 6990 | H15: ='Raw Data'!K61 -> 2928 | I15: =F15/E15 -> 1.0458808 | J15: =D15/E15 -> 0.10750167 | K15: =D15/G15 -> 0.045922747 | L15: =LN(G15) -> 8.8522358 | M15: =(B15-'Raw Data'!D60)/'Raw Data'!D60 -> 0.025263158 | N15: =H15/G15 -> 0.41888412 | O15: ='Raw Data'!L61 -> 12.42
A16: FY16-17 | B16: ='Raw Data'!D62 -> 5967 | C16: ='Raw Data'!E62 -> 732 | D16: ='Raw Data'!F62 -> 19 | E16: ='Raw Data'!G62+'Raw Data'!H62 -> 3011 | F16: ='Raw Data'!I62 -> 2428 | G16: ='Raw Data'!J62 -> 6458 | H16: ='Raw Data'!K62 -> 3177 | I16: =F16/E16 -> 0.80637662 | J16: =D16/E16 -> 0.0063101959 | K16: =D16/G16 -> 0.0029420873 | L16: =LN(G16) -> 8.773075 | M16: =(B16-'Raw Data'!D61)/'Raw Data'!D61 -> 0.1138697 | N16: =H16/G16 -> 0.49194797 | O16: ='Raw Data'!L62 -> 0.72
A17: FY17-18 | B17: ='Raw Data'!D63 -> 6332 | C17: ='Raw Data'!E63 -> 639 | D17: ='Raw Data'!F63 -> 250 | E17: ='Raw Data'!G63+'Raw Data'!H63 -> 3159 | F17: ='Raw Data'!I63 -> 2562 | G17: ='Raw Data'!J63 -> 7044 | H17: ='Raw Data'!K63 -> 3208 | I17: =F17/E17 -> 0.81101614 | J17: =D17/E17 -> 0.079138968 | K17: =D17/G17 -> 0.035491198 | L17: =LN(G17) -> 8.8599315 | M17: =(B17-'Raw Data'!D62)/'Raw Data'!D62 -> 0.061169767 | N17: =H17/G17 -> 0.45542306 | O17: ='Raw Data'!L63 -> 9.67
A18: FY18-19 | B18: ='Raw Data'!D64 -> 6436 | C18: ='Raw Data'!E64 -> 633 | D18: ='Raw Data'!F64 -> 199 | E18: ='Raw Data'!G64+'Raw Data'!H64 -> 2817 | F18: ='Raw Data'!I64 -> 2652 | G18: ='Raw Data'!J64 -> 7014 | H18: ='Raw Data'!K64 -> 3362 | I18: =F18/E18 -> 0.94142705 | J18: =D18/E18 -> 0.070642528 | K18: =D18/G18 -> 0.028371828 | L18: =LN(G18) -> 8.8556634 | M18: =(B18-'Raw Data'!D63)/'Raw Data'!D63 -> 0.01642451 | N18: =H18/G18 -> 0.47932706 | O18: ='Raw Data'!L64 -> 7.71
A19: FY19-20 | B19: ='Raw Data'!D65 -> 6705 | C19: ='Raw Data'!E65 -> 708 | D19: ='Raw Data'!F65 -> 171 | E19: ='Raw Data'!G65+'Raw Data'!H65 -> 2854 | F19: ='Raw Data'!I65 -> 2431 | G19: ='Raw Data'!J65 -> 6815 | H19: ='Raw Data'!K65 -> 3532 | I19: =F19/E19 -> 0.85178697 | J19: =D19/E19 -> 0.059915907 | K19: =D19/G19 -> 0.025091709 | L19: =LN(G19) -> 8.8268813 | M19: =(B19-'Raw Data'!D64)/'Raw Data'!D64 -> 0.041796147 | N19: =H19/G19 -> 0.51826853 | O19: ='Raw Data'!L65 -> 6.62
A20: FY20-21 | B20: ='Raw Data'!D66 -> 4529 | C20: ='Raw Data'!E66 -> 477 | D20: ='Raw Data'!F66 -> 93 | E20: ='Raw Data'!G66+'Raw Data'!H66 -> 2941 | F20: ='Raw Data'!I66 -> 1985 | G20: ='Raw Data'!J66 -> 6609 | H20: ='Raw Data'!K66 -> 3332 | I20: =F20/E20 -> 0.6749405 | J20: =D20/E20 -> 0.031621897 | K20: =D20/G20 -> 0.01407172 | L20: =LN(G20) -> 8.7961876 | M20: =(B20-'Raw Data'!D65)/'Raw Data'!D65 -> -0.32453393 | N20: =H20/G20 -> 0.50416099 | O20: ='Raw Data'!L66 -> 3.58
A21: FY21-22 | B21: ='Raw Data'!D67 -> 7436 | C21: ='Raw Data'!E67 -> 790 | D21: ='Raw Data'!F67 -> 59 | E21: ='Raw Data'!G67+'Raw Data'!H67 -> 3012 | F21: ='Raw Data'!I67 -> 1783 | G21: ='Raw Data'!J67 -> 7413 | H21: ='Raw Data'!K67 -> 3268 | I21: =F21/E21 -> 0.59196547 | J21: =D21/E21 -> 0.019588313 | K21: =D21/G21 -> 0.007958991 | L21: =LN(G21) -> 8.9109905 | M21: =(B21-'Raw Data'!D66)/'Raw Data'!D66 -> 0.64186355 | N21: =H21/G21 -> 0.44084716 | O21: ='Raw Data'!L67 -> 2.28
A22: FY22-23 | B22: ='Raw Data'!D68 -> 7723 | C22: ='Raw Data'!E68 -> 720 | D22: ='Raw Data'!F68 -> 346 | E22: ='Raw Data'!G68+'Raw Data'!H68 -> 3297 | F22: ='Raw Data'!I68 -> 1420 | G22: ='Raw Data'!J68 -> 6398 | H22: ='Raw Data'!K68 -> 3255 | I22: =F22/E22 -> 0.43069457 | J22: =D22/E22 -> 0.10494389 | K22: =D22/G22 -> 0.0540794 | L22: =LN(G22) -> 8.7637407 | M22: =(B22-'Raw Data'!D67)/'Raw Data'!D67 -> 0.038596019 | N22: =H22/G22 -> 0.50875274 | O22: ='Raw Data'!L68 -> 13.23
A23: FY23-24 | B23: ='Raw Data'!D69 -> 7100 | C23: ='Raw Data'!E69 -> 767 | D23: ='Raw Data'!F69 -> 305 | E23: ='Raw Data'!G69+'Raw Data'!H69 -> 3477 | F23: ='Raw Data'!I69 -> 1320 | G23: ='Raw Data'!J69 -> 6729 | H23: ='Raw Data'!K69 -> 3288 | I23: =F23/E23 -> 0.37963762 | J23: =D23/E23 -> 0.087719298 | K23: =D23/G23 -> 0.0453262 | L23: =LN(G23) -> 8.8141818 | M23: =(B23-'Raw Data'!D68)/'Raw Data'!D68 -> -0.080668134 | N23: =H23/G23 -> 0.4886313 | O23: ='Raw Data'!L69 -> 11.65
A24: FY24-25 | B24: ='Raw Data'!D70 -> 6236 | C24: ='Raw Data'!E70 -> 581 | D24: ='Raw Data'!F70 -> 240 | E24: ='Raw Data'!G70+'Raw Data'!H70 -> 3587 | F24: ='Raw Data'!I70 -> 1496 | G24: ='Raw Data'!J70 -> 7324 | H24: ='Raw Data'!K70 -> 3504 | I24: =F24/E24 -> 0.41706161 | J24: =D24/E24 -> 0.06690828 | K24: =D24/G24 -> 0.032768979 | L24: =LN(G24) -> 8.8989119 | M24: =(B24-'Raw Data'!D69)/'Raw Data'!D69 -> -0.12169014 | N24: =H24/G24 -> 0.47842709 | O24: ='Raw Data'!L70 -> 9.18
A25: 10-YR AVERAGE | B25: =AVERAGE(B15:B24) -> 6382.1 | C25: =AVERAGE(C15:C24) -> 685.5 | D25: =AVERAGE(D15:D24) -> 200.3 | E25: =AVERAGE(E15:E24) -> 3114.1 | F25: =AVERAGE(F15:F24) -> 2120 | G25: =AVERAGE(G15:G24) -> 6879.4 | H25: =AVERAGE(H15:H24) -> 3285.4 | I25: =AVERAGE(I15:I24) -> 0.69507873 | ... O25: =AVERAGE(O15:O24) -> 7.706
A27: SD (10-yr) | I27: =STDEV(I15:I24) -> 0.23377797 | J27: =STDEV(J15:J24) -> 0.034601615 | K27: =STDEV(K15:K24) -> 0.016990498 | O27: =STDEV(O15:O24) -> 4.3559721

Sheet Nitin Spinners
A1: Nitin Spinners
A3: Screener Ticker | B3: NITINSPIN
A4: Basis | B4: Standalone
A5: Primary Business | B5: Cotton Yarn, Knitted & Woven Fabric — spinning specialist
A6: Year Established | B6: 1992
A7: Headquarters | B7: Bhilwara, Rajasthan (the 'Textile City of India')
A8: Promoter / Group | B8: Nolkha family
A9: Manufacturing Locations | B9: Hamirgarh (Bhilwara) and Begun (Chittorgarh), Rajasthan
A10: Listed On | B10: NSE & BSE (BSE code: 532698)
A11: Note
A13: 10-Year Financials & Computed Ratios (FY2015-16 to FY2024-25)
A14: FY | B14: Sales | C14: EBIT | D14: Net Profit | E14: Total Equity | F14: Borrowings | G14: Total Assets | H14: Fixed Assets | I14: D/E Ratio | J14: ROE | K14: ROA | L14: Size (ln TA) | M14: Sales Growth % | N14: Tangibility | O14: EPS (Rs.)
A15: FY15-16 | B15: ='Raw Data'!D72 -> 766 | C15: ='Raw Data'!E72 -> 137 | D15: ='Raw Data'!F72 -> 44 | E15: ='Raw Data'!G72+'Raw Data'!H72 -> 206 | F15: ='Raw Data'!I72 -> 352 | G15: ='Raw Data'!J72 -> 635 | H15: ='Raw Data'!K72 -> 399 | I15: =F15/E15 -> 1.7087379 | J15: =D15/E15 -> 0.21359223 | K15: =D15/G15 -> 0.069291339 | L15: =LN(G15) -> 6.453625 | M15: =(B15-'Raw Data'!D71)/'Raw Data'!D71 -> 0.24350649 | N15: =H15/G15 -> 0.62834646 | O15: ='Raw Data'!L72 -> 9.63
A16: FY16-17 | B16: ='Raw Data'!D73 -> 933 | C16: ='Raw Data'!E73 -> 133 | D16: ='Raw Data'!F73 -> 57 | E16: ='Raw Data'!G73+'Raw Data'!H73 -> 264 | F16: ='Raw Data'!I73 -> 568 | G16: ='Raw Data'!J73 -> 885 | H16: ='Raw Data'!K73 -> 613 | I16: =F16/E16 -> 2.1515152 | J16: =D16/E16 -> 0.21590909 | K16: =D16/G16 -> 0.06440678 | L16: =LN(G16) -> 6.7855876 | M16: =(B16-'Raw Data'!D72)/'Raw Data'!D72 -> 0.21801567 | N16: =H16/G16 -> 0.69265537 | O16: ='Raw Data'!L73 -> 12.51
A17: FY17-18 | B17: ='Raw Data'!D74 -> 1145 | C17: ='Raw Data'!E74 -> 155 | D17: ='Raw Data'!F74 -> 52 | E17: ='Raw Data'!G74+'Raw Data'!H74 -> 417 | F17: ='Raw Data'!I74 -> 449 | G17: ='Raw Data'!J74 -> 929 | H17: ='Raw Data'!K74 -> 574 | I17: =F17/E17 -> 1.0767386 | J17: =D17/E17 -> 0.12470024 | K17: =D17/G17 -> 0.055974166 | L17: =LN(G17) -> 6.8341087 | M17: =(B17-'Raw Data'!D73)/'Raw Data'!D73 -> 0.22722401 | N17: =H17/G17 -> 0.61786868 | O17: ='Raw Data'!L74 -> 9.43
A18: FY18-19 | B18: ='Raw Data'!D75 -> 1241 | C18: ='Raw Data'!E75 -> 178 | D18: ='Raw Data'!F75 -> 64 | E18: ='Raw Data'!G75+'Raw Data'!H75 -> 482 | F18: ='Raw Data'!I75 -> 860 | G18: ='Raw Data'!J75 -> 1436 | H18: ='Raw Data'!K75 -> 992 | I18: =F18/E18 -> 1.7842324 | J18: =D18/E18 -> 0.13278008 | K18: =D18/G18 -> 0.044568245 | L18: =LN(G18) -> 7.2696167 | M18: =(B18-'Raw Data'!D74)/'Raw Data'!D74 -> 0.083842795 | N18: =H18/G18 -> 0.6908078 | O18: ='Raw Data'!L75 -> 11.4
A19: FY19-20 | B19: ='Raw Data'!D76 -> 1436 | C19: ='Raw Data'!E76 -> 170 | D19: ='Raw Data'!F76 -> 24 | E19: ='Raw Data'!G76+'Raw Data'!H76 -> 494 | F19: ='Raw Data'!I76 -> 1040 | G19: ='Raw Data'!J76 -> 1645 | H19: ='Raw Data'!K76 -> 1140 | I19: =F19/E19 -> 2.1052632 | J19: =D19/E19 -> 0.048582996 | K19: =D19/G19 -> 0.014589666 | L19: =LN(G19) -> 7.4054957 | M19: =(B19-'Raw Data'!D75)/'Raw Data'!D75 -> 0.15713135 | N19: =H19/G19 -> 0.69300912 | O19: ='Raw Data'!L76 -> 4.24
A20: FY20-21 | B20: ='Raw Data'!D77 -> 1622 | C20: ='Raw Data'!E77 -> 257 | D20: ='Raw Data'!F77 -> 69 | E20: ='Raw Data'!G77+'Raw Data'!H77 -> 563 | F20: ='Raw Data'!I77 -> 962 | G20: ='Raw Data'!J77 -> 1676 | H20: ='Raw Data'!K77 -> 1062 | I20: =F20/E20 -> 1.7087034 | J20: =D20/E20 -> 0.12255773 | K20: =D20/G20 -> 0.041169451 | L20: =LN(G20) -> 7.4241653 | M20: =(B20-'Raw Data'!D76)/'Raw Data'!D76 -> 0.12952646 | N20: =H20/G20 -> 0.63365155 | O20: ='Raw Data'!L77 -> 12.25
A21: FY21-22 | B21: ='Raw Data'!D78 -> 2690 | C21: ='Raw Data'!E78 -> 652 | D21: ='Raw Data'!F78 -> 326 | E21: ='Raw Data'!G78+'Raw Data'!H78 -> 876 | F21: ='Raw Data'!I78 -> 689 | G21: ='Raw Data'!J78 -> 1824 | H21: ='Raw Data'!K78 -> 1012 | I21: =F21/E21 -> 0.78652968 | J21: =D21/E21 -> 0.37214612 | K21: =D21/G21 -> 0.17872807 | L21: =LN(G21) -> 7.5087872 | M21: =(B21-'Raw Data'!D77)/'Raw Data'!D77 -> 0.65844636 | N21: =H21/G21 -> 0.55482456 | O21: ='Raw Data'!L78 -> 58.01
A22: FY22-23 | B22: ='Raw Data'!D79 -> 2404 | C22: ='Raw Data'!E79 -> 297 | D22: ='Raw Data'!F79 -> 165 | E22: ='Raw Data'!G79+'Raw Data'!H79 -> 1029 | F22: ='Raw Data'!I79 -> 980 | G22: ='Raw Data'!J79 -> 2218 | H22: ='Raw Data'!K79 -> 1351 | I22: =F22/E22 -> 0.95238095 | J22: =D22/E22 -> 0.16034985 | K22: =D22/G22 -> 0.074391344 | L22: =LN(G22) -> 7.7043612 | M22: =(B22-'Raw Data'!D78)/'Raw Data'!D78 -> -0.1063197 | N22: =H22/G22 -> 0.6091073 | O22: ='Raw Data'!L79 -> 29.32
A23: FY23-24 | B23: ='Raw Data'!D80 -> 2902 | C23: ='Raw Data'!E80 -> 377 | D23: ='Raw Data'!F80 -> 132 | E23: ='Raw Data'!G80+'Raw Data'!H80 -> 1146 | F23: ='Raw Data'!I80 -> 1339 | G23: ='Raw Data'!J80 -> 2717 | H23: ='Raw Data'!K80 -> 1711 | I23: =F23/E23 -> 1.1684119 | J23: =D23/E23 -> 0.11518325 | K23: =D23/G23 -> 0.048582996 | L23: =LN(G23) -> 7.9072836 | M23: =(B23-'Raw Data'!D79)/'Raw Data'!D79 -> 0.20715474 | N23: =H23/G23 -> 0.62973868 | O23: ='Raw Data'!L80 -> 23.39
A24: FY24-25 | B24: ='Raw Data'!D81 -> 3300 | C24: ='Raw Data'!E81 -> 471 | D24: ='Raw Data'!F81 -> 175 | E24: ='Raw Data'!G81+'Raw Data'!H81 -> 1311 | F24: ='Raw Data'!I81 -> 1165 | G24: ='Raw Data'!J81 -> 2732 | H24: ='Raw Data'!K81 -> 1584 | I24: =F24/E24 -> 0.88863463 | J24: =D24/E24 -> 0.13348589 | K24: =D24/G24 -> 0.064055637 | L24: =LN(G24) -> 7.9127892 | M24: =(B24-'Raw Data'!D80)/'Raw Data'!D80 -> 0.1371468 | N24: =H24/G24 -> 0.57979502 | O24: ='Raw Data'!L81 -> 31.2
A25: 10-YR AVERAGE | B25: =AVERAGE(B15:B24) -> 1843.9 | C25: =AVERAGE(C15:C24) -> 282.7 | D25: =AVERAGE(D15:D24) -> 110.8 | E25: =AVERAGE(E15:E24) -> 678.8 | F25: =AVERAGE(F15:F24) -> 840.4 | G25: =AVERAGE(G15:G24) -> 1669.7 | H25: =AVERAGE(H15:H24) -> 1043.8 | I25: =AVERAGE(I15:I24) -> 1.4331148 | ... O25: =AVERAGE(O15:O24) -> 20.138
A27: SD (10-yr) | I27: =STDEV(I15:I24) -> 0.51486684 | J27: =STDEV(J15:J24) -> 0.087790097 | K27: =STDEV(K15:K24) -> 0.043354037 | O27: =STDEV(O15:O24) -> 16.076643

Sheet Sutlej Textiles
A1: Sutlej Textiles
A3: Screener Ticker | B3: SUTLEJTEX
A4: Basis | B4: Standalone
A5: Primary Business | B5: Yarn, Home Textiles — spinning specialist
A6: Year Established | B6: Current entity incorporated 2005 (demerger); heritage traces to Sutlej Cotton Mills, 1934
A7: Headquarters | B7: Registered office: Jaipur, Rajasthan
A8: Promoter / Group | B8: KK Birla Group — founder Dr. Krishna Kumar Birla
A9: Manufacturing Locations | B9: Bhawanimandi (Rajasthan), Baddi (Himachal Pradesh), Kathua (J&K), Bhillad (Gujarat)
A10: Listed On | B10: NSE & BSE
A11: Note
A13: 10-Year Financials & Computed Ratios (FY2015-16 to FY2024-25)
A14: FY | B14: Sales | C14: EBIT | D14: Net Profit | E14: Total Equity | F14: Borrowings | G14: Total Assets | H14: Fixed Assets | I14: D/E Ratio | J14: ROE | K14: ROA | L14: Size (ln TA) | M14: Sales Growth % | N14: Tangibility | O14: EPS (Rs.)
A15: FY15-16 | B15: ='Raw Data'!D83 -> 2074 | C15: ='Raw Data'!E83 -> 263 | D15: ='Raw Data'!F83 -> 143 | E15: ='Raw Data'!G83+'Raw Data'!H83 -> 683 | F15: ='Raw Data'!I83 -> 804 | G15: ='Raw Data'!J83 -> 1675 | H15: ='Raw Data'!K83 -> 877 | I15: =F15/E15 -> 1.1771596 | J15: =D15/E15 -> 0.20937042 | K15: =D15/G15 -> 0.085373134 | L15: =LN(G15) -> 7.4235684 | M15: =(B15-'Raw Data'!D82)/'Raw Data'!D82 -> 0.11087306 | N15: =H15/G15 -> 0.52358209 | O15: ='Raw Data'!L83 -> 8.76
A16: FY16-17 | B16: ='Raw Data'!D84 -> 2249 | C16: ='Raw Data'!E84 -> 282 | D16: ='Raw Data'!F84 -> 158 | E16: ='Raw Data'!G84+'Raw Data'!H84 -> 816 | F16: ='Raw Data'!I84 -> 1036 | G16: ='Raw Data'!J84 -> 2045 | H16: ='Raw Data'!K84 -> 1139 | I16: =F16/E16 -> 1.2696078 | J16: =D16/E16 -> 0.19362745 | K16: =D16/G16 -> 0.077261614 | L16: =LN(G16) -> 7.6231531 | M16: =(B16-'Raw Data'!D83)/'Raw Data'!D83 -> 0.084378014 | N16: =H16/G16 -> 0.55696822 | O16: ='Raw Data'!L84 -> 9.64
A17: FY17-18 | B17: ='Raw Data'!D85 -> 2453 | C17: ='Raw Data'!E85 -> 247 | D17: ='Raw Data'!F85 -> 113 | E17: ='Raw Data'!G85+'Raw Data'!H85 -> 906 | F17: ='Raw Data'!I85 -> 1047 | G17: ='Raw Data'!J85 -> 2182 | H17: ='Raw Data'!K85 -> 1119 | I17: =F17/E17 -> 1.1556291 | J17: =D17/E17 -> 0.12472406 | K17: =D17/G17 -> 0.051787351 | L17: =LN(G17) -> 7.6879972 | M17: =(B17-'Raw Data'!D84)/'Raw Data'!D84 -> 0.090706981 | N17: =H17/G17 -> 0.51283226 | O17: ='Raw Data'!L85 -> 6.91
A18: FY18-19 | B18: ='Raw Data'!D86 -> 2562 | C18: ='Raw Data'!E86 -> 219 | D18: ='Raw Data'!F86 -> 66 | E18: ='Raw Data'!G86+'Raw Data'!H86 -> 946 | F18: ='Raw Data'!I86 -> 923 | G18: ='Raw Data'!J86 -> 2131 | H18: ='Raw Data'!K86 -> 1074 | I18: =F18/E18 -> 0.9756871 | J18: =D18/E18 -> 0.069767442 | K18: =D18/G18 -> 0.030971375 | L18: =LN(G18) -> 7.6643466 | M18: =(B18-'Raw Data'!D85)/'Raw Data'!D85 -> 0.044435385 | N18: =H18/G18 -> 0.50398874 | O18: ='Raw Data'!L86 -> 4.01
A19: FY19-20 | B19: ='Raw Data'!D87 -> 2379 | C19: ='Raw Data'!E87 -> 178 | D19: ='Raw Data'!F87 -> 36 | E19: ='Raw Data'!G87+'Raw Data'!H87 -> 971 | F19: ='Raw Data'!I87 -> 868 | G19: ='Raw Data'!J87 -> 2118 | H19: ='Raw Data'!K87 -> 1210 | I19: =F19/E19 -> 0.89392379 | J19: =D19/E19 -> 0.03707518 | K19: =D19/G19 -> 0.016997167 | L19: =LN(G19) -> 7.6582275 | M19: =(B19-'Raw Data'!D86)/'Raw Data'!D86 -> -0.071428571 | N19: =H19/G19 -> 0.57129367 | O19: ='Raw Data'!L87 -> 2.2
A20: FY20-21 | B20: ='Raw Data'!D88 -> 1861 | C20: ='Raw Data'!E88 -> 115 | D20: ='Raw Data'!F88 -> 10 | E20: ='Raw Data'!G88+'Raw Data'!H88 -> 980 | F20: ='Raw Data'!I88 -> 901 | G20: ='Raw Data'!J88 -> 2149 | H20: ='Raw Data'!K88 -> 1231 | I20: =F20/E20 -> 0.91938776 | J20: =D20/E20 -> 0.010204082 | K20: =D20/G20 -> 0.0046533271 | L20: =LN(G20) -> 7.6727579 | M20: =(B20-'Raw Data'!D87)/'Raw Data'!D87 -> -0.21773855 | N20: =H20/G20 -> 0.57282457 | O20: ='Raw Data'!L88 -> 0.58
A21: FY21-22 | B21: ='Raw Data'!D89 -> 3042 | C21: ='Raw Data'!E89 -> 387 | D21: ='Raw Data'!F89 -> 156 | E21: ='Raw Data'!G89+'Raw Data'!H89 -> 1130 | F21: ='Raw Data'!I89 -> 938 | G21: ='Raw Data'!J89 -> 2442 | H21: ='Raw Data'!K89 -> 1187 | I21: =F21/E21 -> 0.8300885 | J21: =D21/E21 -> 0.1380531 | K21: =D21/G21 -> 0.063882064 | L21: =LN(G21) -> 7.8005727 | M21: =(B21-'Raw Data'!D88)/'Raw Data'!D88 -> 0.63460505 | N21: =H21/G21 -> 0.48607699 | O21: ='Raw Data'!L89 -> 9.5
A22: FY22-23 | B22: ='Raw Data'!D90 -> 3039 | C22: ='Raw Data'!E90 -> 264 | D22: ='Raw Data'!F90 -> 23 | E22: ='Raw Data'!G90+'Raw Data'!H90 -> 1123 | F22: ='Raw Data'!I90 -> 933 | G22: ='Raw Data'!J90 -> 2421 | H22: ='Raw Data'!K90 -> 1121 | I22: =F22/E22 -> 0.83081033 | J22: =D22/E22 -> 0.020480855 | K22: =D22/G22 -> 0.0095002065 | L22: =LN(G22) -> 7.791936 | M22: =(B22-'Raw Data'!D89)/'Raw Data'!D89 -> -0.00098619329 | N22: =H22/G22 -> 0.46303181 | O22: ='Raw Data'!L90 -> 1.39
A23: FY23-24 | B23: ='Raw Data'!D91 -> 2672 | C23: ='Raw Data'!E91 -> -29 | D23: ='Raw Data'!F91 -> -135 | E23: ='Raw Data'!G91+'Raw Data'!H91 -> 976 | F23: ='Raw Data'!I91 -> 826 | G23: ='Raw Data'!J91 -> 2097 | H23: ='Raw Data'!K91 -> 1063 | I23: =F23/E23 -> 0.84631148 | J23: =D23/E23 -> -0.13831967 | K23: =D23/G23 -> -0.064377682 | L23: =LN(G23) -> 7.648263 | M23: =(B23-'Raw Data'!D90)/'Raw Data'!D90 -> -0.12076341 | N23: =H23/G23 -> 0.50691464 | O23: ='Raw Data'!L91 -> -8.22
A24: FY24-25 | B24: ='Raw Data'!D92 -> 2642 | C24: ='Raw Data'!E92 -> 46 | D24: ='Raw Data'!F92 -> -84 | E24: ='Raw Data'!G92+'Raw Data'!H92 -> 894 | F24: ='Raw Data'!I92 -> 877 | G24: ='Raw Data'!J92 -> 2043 | H24: ='Raw Data'!K92 -> 1010 | I24: =F24/E24 -> 0.98098434 | J24: =D24/E24 -> -0.093959732 | K24: =D24/G24 -> -0.041116006 | L24: =LN(G24) -> 7.6221746 | M24: =(B24-'Raw Data'!D91)/'Raw Data'!D91 -> -0.011227545 | N24: =H24/G24 -> 0.49437102 | O24: ='Raw Data'!L92 -> -5.14
A25: 10-YR AVERAGE | B25: =AVERAGE(B15:B24) -> 2497.3 | C25: =AVERAGE(C15:C24) -> 197.2 | D25: =AVERAGE(D15:D24) -> 48.6 | E25: =AVERAGE(E15:E24) -> 942.5 | F25: =AVERAGE(F15:F24) -> 915.3 | G25: =AVERAGE(G15:G24) -> 2130.3 | H25: =AVERAGE(H15:H24) -> 1103.1 | I25: =AVERAGE(I15:I24) -> 0.98795899 | ... O25: =AVERAGE(O15:O24) -> 2.963
A27: SD (10-yr) | I27: =STDEV(I15:I24) -> 0.1586971 | J27: =STDEV(J15:J24) -> 0.11453383 | K27: =STDEV(K15:K24) -> 0.049099101 | O27: =STDEV(O15:O24) -> 6.1196243

Sheet Gokaldas Exports
A1: Gokaldas Exports
A3: Screener Ticker | B3: GOKEX
A4: Basis | B4: Standalone
A5: Primary Business | B5: Apparel / Garment Exports
A6: Year Established | B6: 1979
A7: Headquarters | B7: Bengaluru, Karnataka
A8: Promoter / Group | B8: Founded by Jhamandas Hinduja; Blackstone Group has held majority stake since 2007
A9: Manufacturing Locations | B9: Bengaluru region, Karnataka; also Kenya and Ethiopia
A10: Listed On | B10: NSE & BSE
A11: Note
A13: 10-Year Financials & Computed Ratios (FY2015-16 to FY2024-25)
A14: FY | B14: Sales | C14: EBIT | D14: Net Profit | E14: Total Equity | F14: Borrowings | G14: Total Assets | H14: Fixed Assets | I14: D/E Ratio | J14: ROE | K14: ROA | L14: Size (ln TA) | M14: Sales Growth % | N14: Tangibility | O14: EPS (Rs.)
A15: FY15-16 | B15: ='Raw Data'!D94 -> 1123 | C15: ='Raw Data'!E94 -> 37 | D15: ='Raw Data'!F94 -> 61 | E15: ='Raw Data'!G94+'Raw Data'!H94 -> 212 | F15: ='Raw Data'!I94 -> 343 | G15: ='Raw Data'!J94 -> 725 | H15: ='Raw Data'!K94 -> 94 | I15: =F15/E15 -> 1.6179245 | J15: =D15/E15 -> 0.28773585 | K15: =D15/G15 -> 0.084137931 | L15: =LN(G15) -> 6.5861717 | M15: =(B15-'Raw Data'!D93)/'Raw Data'!D93 -> 0.04953271 | N15: =H15/G15 -> 0.12965517 | O15: ='Raw Data'!L94 -> 17.44
A16: FY16-17 | B16: ='Raw Data'!D95 -> 915 | C16: ='Raw Data'!E95 -> -31 | D16: ='Raw Data'!F95 -> -46 | E16: ='Raw Data'!G95+'Raw Data'!H95 -> 165 | F16: ='Raw Data'!I95 -> 474 | G16: ='Raw Data'!J95 -> 794 | H16: ='Raw Data'!K95 -> 95 | I16: =F16/E16 -> 2.8727273 | J16: =D16/E16 -> -0.27878788 | K16: =D16/G16 -> -0.057934509 | L16: =LN(G16) -> 6.6770835 | M16: =(B16-'Raw Data'!D94)/'Raw Data'!D94 -> -0.18521817 | N16: =H16/G16 -> 0.11964736 | O16: ='Raw Data'!L95 -> -13.23
A17: FY17-18 | B17: ='Raw Data'!D96 -> 1031 | C17: ='Raw Data'!E96 -> -23 | D17: ='Raw Data'!F96 -> -31 | E17: ='Raw Data'!G96+'Raw Data'!H96 -> 130 | F17: ='Raw Data'!I96 -> 472 | G17: ='Raw Data'!J96 -> 794 | H17: ='Raw Data'!K96 -> 95 | I17: =F17/E17 -> 3.6307692 | J17: =D17/E17 -> -0.23846154 | K17: =D17/G17 -> -0.039042821 | L17: =LN(G17) -> 6.6770835 | M17: =(B17-'Raw Data'!D95)/'Raw Data'!D95 -> 0.12677596 | N17: =H17/G17 -> 0.11964736 | O17: ='Raw Data'!L96 -> -8.83
A18: FY18-19 | B18: ='Raw Data'!D97 -> 1173 | C18: ='Raw Data'!E97 -> 62 | D18: ='Raw Data'!F97 -> 26 | E18: ='Raw Data'!G97+'Raw Data'!H97 -> 239 | F18: ='Raw Data'!I97 -> 381 | G18: ='Raw Data'!J97 -> 823 | H18: ='Raw Data'!K97 -> 108 | I18: =F18/E18 -> 1.5941423 | J18: =D18/E18 -> 0.10878661 | K18: =D18/G18 -> 0.031591738 | L18: =LN(G18) -> 6.7129562 | M18: =(B18-'Raw Data'!D96)/'Raw Data'!D96 -> 0.13773036 | N18: =H18/G18 -> 0.13122722 | O18: ='Raw Data'!L97 -> 5.99
A19: FY19-20 | B19: ='Raw Data'!D98 -> 1368 | C19: ='Raw Data'!E98 -> 87 | D19: ='Raw Data'!F98 -> 32 | E19: ='Raw Data'!G98+'Raw Data'!H98 -> 228 | F19: ='Raw Data'!I98 -> 440 | G19: ='Raw Data'!J98 -> 939 | H19: ='Raw Data'!K98 -> 172 | I19: =F19/E19 -> 1.9298246 | J19: =D19/E19 -> 0.14035088 | K19: =D19/G19 -> 0.034078807 | L19: =LN(G19) -> 6.8448155 | M19: =(B19-'Raw Data'!D97)/'Raw Data'!D97 -> 0.16624041 | N19: =H19/G19 -> 0.18317359 | O19: ='Raw Data'!L98 -> 7.56
A20: FY20-21 | B20: ='Raw Data'!D99 -> 1209 | C20: ='Raw Data'!E99 -> 101 | D20: ='Raw Data'!F99 -> 26 | E20: ='Raw Data'!G99+'Raw Data'!H99 -> 291 | F20: ='Raw Data'!I99 -> 476 | G20: ='Raw Data'!J99 -> 1005 | H20: ='Raw Data'!K99 -> 235 | I20: =F20/E20 -> 1.6357388 | J20: =D20/E20 -> 0.089347079 | K20: =D20/G20 -> 0.025870647 | L20: =LN(G20) -> 6.9127428 | M20: =(B20-'Raw Data'!D98)/'Raw Data'!D98 -> -0.11622807 | N20: =H20/G20 -> 0.23383085 | O20: ='Raw Data'!L99 -> 6.12
